RPC_ERROR
Odoo Server Error
Traceback (most recent call last):
  File "/usr/lib/python3/dist-packages/odoo/http.py", line 1764, in _serve_db
    return service_model.retrying(self._serve_ir_http, self.env)
  File "/usr/lib/python3/dist-packages/odoo/service/model.py", line 133, in retrying
    result = func()
  File "/usr/lib/python3/dist-packages/odoo/http.py", line 1791, in _serve_ir_http
    response = self.dispatcher.dispatch(rule.endpoint, args)
  File "/usr/lib/python3/dist-packages/odoo/http.py", line 1995, in dispatch
    result = self.request.registry['ir.http']._dispatch(endpoint)
  File "/usr/lib/python3/dist-packages/odoo/addons/base/models/ir_http.py", line 222, in _dispatch
    result = endpoint(**request.params)
  File "/usr/lib/python3/dist-packages/odoo/http.py", line 741, in route_wrapper
    result = endpoint(self, *args, **params_ok)
  File "/usr/lib/python3/dist-packages/odoo/addons/web/controllers/dataset.py", line 28, in call_button
    action = self._call_kw(model, method, args, kwargs)
  File "/usr/lib/python3/dist-packages/odoo/addons/web/controllers/dataset.py", line 20, in _call_kw
    return call_kw(request.env[model], method, args, kwargs)
  File "/usr/lib/python3/dist-packages/odoo/api.py", line 468, in call_kw
    result = _call_kw_multi(method, model, args, kwargs)
  File "/usr/lib/python3/dist-packages/odoo/api.py", line 453, in _call_kw_multi
    result = method(recs, *args, **kwargs)
  File "<decorator-gen-83>", line 2, in button_immediate_upgrade
  File "/usr/lib/python3/dist-packages/odoo/addons/base/models/ir_module.py", line 75, in check_and_log
    return method(self, *args, **kwargs)
  File "/usr/lib/python3/dist-packages/odoo/addons/base/models/ir_module.py", line 657, in button_immediate_upgrade
    return self._button_immediate_function(self.env.registry[self._name].button_upgrade)
  File "/usr/lib/python3/dist-packages/odoo/addons/base/models/ir_module.py", line 590, in _button_immediate_function
    registry = modules.registry.Registry.new(self._cr.dbname, update_module=True)
  File "<decorator-gen-16>", line 2, in new
  File "/usr/lib/python3/dist-packages/odoo/tools/func.py", line 87, in locked
    return func(inst, *args, **kwargs)
  File "/usr/lib/python3/dist-packages/odoo/modules/registry.py", line 113, in new
    odoo.modules.load_modules(registry, force_demo, status, update_module)
  File "/usr/lib/python3/dist-packages/odoo/modules/loading.py", line 476, in load_modules
    processed_modules += load_marked_modules(env, graph,
  File "/usr/lib/python3/dist-packages/odoo/modules/loading.py", line 364, in load_marked_modules
    loaded, processed = load_module_graph(
  File "/usr/lib/python3/dist-packages/odoo/modules/loading.py", line 227, in load_module_graph
    load_data(env, idref, mode, kind='data', package=package)
  File "/usr/lib/python3/dist-packages/odoo/modules/loading.py", line 71, in load_data
    tools.convert_file(env, package.name, filename, idref, mode, noupdate, kind)
  File "/usr/lib/python3/dist-packages/odoo/tools/convert.py", line 623, in convert_file
    convert_csv_import(env, module, pathname, fp.read(), idref, mode, noupdate)
  File "/usr/lib/python3/dist-packages/odoo/tools/convert.py", line 669, in convert_csv_import
    raise Exception(_('Module loading %s failed: file %s could not be processed:\n %s') % (module, fname, warning_msg))
Exception: Impossible de charger le module real_estate échec : fichier real_estate/security/ir.model.access.csv :
Aucun enregistrement trouvé pour id externe 'base.group_admin' dans le champ 'Group'

The above server error caused the following client error:
RPC_ERROR: Odoo Server Error
    RPC_ERROR
        at makeErrorFromResponse (http://localhost:8069/web/assets/d92094d/web.assets_web.min.js:2883:163)
        at XMLHttpRequest.<anonymous> (http://localhost:8069/web/assets/d92094d/web.assets_web.min.js:2887:13)